Workbook

Sheet 28434
A1: Train Number | B1: Train Category | C1: Origin | D1: Destination | E1: Mezzo di trazione | F1: Vel. veicoli e Rango
A2: 28434 | B2: INVIO | C2: PIOLTELLO LIM. | D2: MILANO CERTOSA | E2: ALe 711/710 (2 + 3 | F2: 140 B
A4: Stations | B4: Type of Stop | C4: Arrival time | D4: Departure time | E4: Platform Track Number | F4: EGTRAIN Tracklines
A5: BRESCIA
A6: Ospitaletto T
A7: ROVATO
A8: Chiari
A9: Calcio
A10: Romano
A11: Morengo Bariano
A12: Vidalengo
A13: TREVIGLIO
A14: P.M. Bivio Adda
A15: Bivio Casirate
A16: Melzo
... A18: Vignate
A19: PIOLTELLO LIM. | B19: Origin | D19: -17880 | E19: 1tr | F19: B3
A20: Segrate | B20: Pass | D20: -17760
A21: MILANO LAMBRATE

Sheet 51044-51045
A1: Train Number | B1: Train Category | C1: Origin | D1: Destination | E1: Mezzo di trazione | F1: Vel. veicoli e Rango
A2: 51044-51045 | B2: TCS | C2: MELZO SCALO | D2: LA SPEZIA MIGL. | E2: E483 | F2: 120 A
A4: Stations | B4: Type of Stop | C4: Arrival time | D4: Departure time | E4: Platform Track Number | F4: EGTRAIN Tracklines
A5: BRESCIA
A6: Ospitaletto T
A7: ROVATO
A8: Chiari
A9: Calcio
A10: Romano
A11: Morengo Bariano
A12: Vidalengo
A13: TREVIGLIO
A14: P.M. Bivio Adda
A15: Bivio Casirate
A16: Melzo
A17: MELZO SCALO | B17: Origin | D17: -7320 | E17: 3 | F17: B7
A18: Vignate
A19: PIOLTELLO LIM. | B19: Pass | D19: -7020 | E19: 4 | F19: B4
A20: Segrate
A21: MILANO LAMBRATE

Sheet 51054-51055-51054
A1: Train Number | B1: Train Category | C1: Origin | D1: Destination | E1: Mezzo di trazione | F1: Vel. veicoli e Rango
A2: 51054-51055-51054 | B2: TCS | C2: MELZO SCALO | D2: Ge Voltri FM | E2: E483 | F2: 120 A
A4: Stations | B4: Type of Stop | C4: Arrival time | D4: Departure time | E4: Platform Track Number | F4: EGTRAIN Tracklines
A5: BRESCIA
A6: Ospitaletto T
A7: ROVATO
A8: Chiari
A9: Calcio
A10: Romano
A11: Morengo Bariano
A12: Vidalengo
A13: TREVIGLIO
A14: P.M. Bivio Adda
A15: Bivio Casirate
A16: Melzo
A17: MELZO SCALO | B17: Origin | D17: -6780 | E17: 5 | F17: B9
A18: Vignate
A19: PIOLTELLO LIM. | B19: Pass | D19: -6480 | E19: 4 | F19: B4
A20: Segrate
A21: MILANO LAMBRATE

Sheet 41038
A1: Train Number | B1: Train Category | C1: Origin | D1: Destination | E1: Mezzo di trazione | F1: Vel. veicoli e Rango
A2: 41038 | B2: TEC | C2: MELZO SCALO | D2: CHIASSO SMIST. | E2: E186 | F2: 100 A
A4: Stations | B4: Type of Stop | C4: Arrival time | D4: Departure time | E4: Platform Track Number | F4: EGTRAIN Tracklines
A5: BRESCIA
A6: Ospitaletto T
A7: ROVATO
A8: Chiari
A9: Calcio
A10: Romano
A11: Morengo Bariano
A12: Vidalengo
A13: TREVIGLIO
A14: P.M. Bivio Adda
A15: Bivio Casirate
A16: Melzo
A17: MELZO SCALO | B17: Origin | D17: -4620 | E17: 4 | F17: B8
A18: Vignate
A19: PIOLTELLO LIM. | B19: Pass | D19: -4260 | E19: 4 | F19: B4
A20: Segrate
A21: MILANO LAMBRATE | B21: Pass | D21: -3720

Sheet 2600
A1: Train Number | B1: Train Category | C1: Origin | D1: Destination | E1: Mezzo di trazione | F1: Vel. veicoli e Rango
A2: 2600 | B2: REG | C2: BERGAMO | D2: MILANO CENTRALE | E2: E464 np | F2: 160 B
A4: Stations | B4: Type of Stop | C4: Arrival time | D4: Departure time | E4: Platform Track Number | F4: EGTRAIN Tracklines
A5: BRESCIA
A6: Ospitaletto T
A7: ROVATO
A8: Chiari
A9: Calcio
A10: Romano
A11: Morengo Bariano
A12: Vidalengo
A13: TREVIGLIO
A14: P.M. Bivio Adda | B14: Pass | D14: -2400 | E14: 1 | F14: B12
A15: Bivio Casirate | B15: Pass | D15: -2340
A16: Melzo
A17: MELZO SCALO | B17: Pass | D17: -2100 | E17: 2 | F17: B4
A18: Vignate
A19: PIOLTELLO LIM. | B19: Stop | C19: -1800 | D19: -1740 | E19: 4 | F19: B4
A20: Segrate
A21: MILANO LAMBRATE | B21: Stop | C21: -1260 | D21: -1140

Sheet 41072
A1: Train Number | B1: Train Category | C1: Origin | D1: Destination | E1: Mezzo di trazione | F1: Vel. veicoli e Rango
A2: 41072 | B2: TEC | C2: MELZO SCALO | D2: LUINO | E2: E475 | F2: 100 A
A4: Stations | B4: Type of Stop | C4: Arrival time | D4: Departure time | E4: Platform Track Number | F4: EGTRAIN Tracklines
A5: BRESCIA
A6: Ospitaletto T
A7: ROVATO
A8: Chiari
A9: Calcio
A10: Romano
A11: Morengo Bariano
A12: Vidalengo
A13: TREVIGLIO
A14: P.M. Bivio Adda
A15: Bivio Casirate
A16: Melzo
A17: MELZO SCALO | B17: Origin | D17: -1680 | E17: 4 | F17: B8
A18: Vignate
A19: PIOLTELLO LIM. | B19: Pass | D19: -1380 | E19: 4 | F19: B4
A20: Segrate
A21: MILANO LAMBRATE | B21: Pass | D21: -780

Sheet 10712
A1: Train Number | B1: Train Category | C1: Origin | D1: Destination | E1: Mezzo di trazione | F1: Vel. veicoli e Rango
A2: 10712 | B2: REG | C2: BRESCIA | D2: MI.GRECO PIRELLI | E2: E464 np | F2: 140 B
A4: Stations | B4: Type of Stop | C4: Arrival time | D4: Departure time | E4: Platform Track Number | F4: EGTRAIN Tracklines
A5: BRESCIA | B5: Origin | D5: -4920
A6: Ospitaletto T | B6: Stop | C6: -4500 | D6: -4440 | E6: 2 | F6: B14
A7: ROVATO | B7: Stop | C7: -4140 | D7: -4080 | E7: 3 | F7: B14
A8: Chiari | B8: Stop | C8: -3840 | D8: -3780
A9: Calcio | B9: Stop | C9: -3480 | D9: -3420
A10: Romano | B10: Stop | C10: -3120 | D10: -3060 | E10: 1 | F10: B14
A11: Morengo Bariano | B11: Stop | C11: -2880 | D11: -2820
A12: Vidalengo | B12: Stop | C12: -2580 | D12: -2520
A13: TREVIGLIO | B13: Stop | C13: -2220 | D13: -2100 | E13: 4 | F13: B14
A14: P.M. Bivio Adda | B14: Pass | D14: -1980 | E14: 4 | F14: B1
A15: Bivio Casirate
A16: Melzo | B16: Stop | C16: -1140 | D16: -1080
A17: MELZO SCALO | B17: Pass | D17: -1020 | E17: 2N | F17: B1
A18: Vignate | B18: Stop | C18: -900 | D18: -840
A19: PIOLTELLO LIM. | B19: Stop | C19: -600 | D19: -540 | E19: 2 | F19: B1
A20: Segrate | B20: Pass | D20: -360
A21: MILANO LAMBRATE | B21: Stop | C21: 0 | D21: 120

Sheet 23004
A1: Train Number | B1: Train Category | C1: Origin | D1: Destination | E1: Mezzo di trazione | F1: Vel. veicoli e Rango
A2: 23004 | B2: REG | C2: TREVIGLIO | D2: VARESE | E2: ALe 711/710 (4 + 4 | F2: 140 B
A4: Stations | B4: Type of Stop | C4: Arrival time | D4: Departure time | E4: Platform Track Number | F4: EGTRAIN Tracklines
G6: 71.653
G7: 65.827
G8: 59.778
G9: 53.018
G10: 46.052
G11: 42.117
A12: Entrance on Route | D12: =C18-55 -> 65 | G12: 37.146
A13: TREVIGLIO | B13: Origin | D13: -1200 | E13: 1 | F13: B25 | G13: 33.143
A14: P.M. Bivio Adda | B14: Pass | D14: -1020 | E14: 4 | F14: B1 | G14: 29.25
A15: Bivio Casirate | G15: 27.425
A16: Melzo | B16: Stop | C16: -120 | D16: -60 | G16: 19.6
A17: MELZO SCALO | B17: Pass | D17: 0 | E17: 2N | F17: B1 | G17: 18.75
A18: Vignate | B18: Stop | C18: 120 | D18: 180 | G18: 16.09
A19: PIOLTELLO LIM. | B19: Stop | C19: 420 | D19: 480 | E19: 2 | F19: B1 | G19: 12.31
A20: Segrate | B20: Stop | C20: 660 | D20: 720 | G20: 9.9
A21: MILANO LAMBRATE

Sheet 44730-44731
A1: Train Number | B1: Train Category | C1: Origin | D1: Destination | E1: Mezzo di trazione | F1: Vel. veicoli e Rango
A2: 44730-44731 | B2: MRI | C2: VILLA OPICINA | D2: Cassano Spinola | E2: E483 | F2: 100 A
A4: Stations | B4: Type of Stop | C4: Arrival time | D4: Departure time | E4: Platform Track Number | F4: EGTRAIN Tracklines
A5: BRESCIA | B5: Pass | D5: -4020
A6: Ospitaletto T | B6: Pass | D6: -3540 | E6: 2 | F6: B14
A7: ROVATO | B7: Pass | D7: -3240 | E7: 3 | F7: B14
A8: Chiari | B8: Pass | D8: -2640
A9: Calcio | B9: Pass | D9: -2220
A10: Romano | B10: Pass | D10: -1920 | E10: 1 | F10: B14
A11: Morengo Bariano | B11: Pass | D11: -1680
A12: Vidalengo | B12: Pass | D12: -1380
A13: TREVIGLIO | B13: Pass | D13: -1140 | E13: 6 | F13: B12
A14: P.M. Bivio Adda | B14: Pass | D14: -1020 | E14: 1 | F14: B12
A15: Bivio Casirate | B15: Pass | D15: -900
A16: Melzo
A17: MELZO SCALO | B17: Pass | D17: -600 | E17: 2 | F17: B4
A18: Vignate
A19: PIOLTELLO LIM. | B19: Pass | D19: -300 | E19: 4 | F19: B4
A20: Segrate
A21: MILANO LAMBRATE

Sheet 4900
A1: Train Number | B1: Train Category | C1: Origin | D1: Destination | E1: Mezzo di trazione | F1: Vel. veicoli e Rango
A2: 4900 | B2: REG | C2: BRESCIA | D2: BERGAMO | E2: ALe 582 (1M + 3R) | F2: 140 C
A4: Stations | B4: Type of Stop | C4: Arrival time | D4: Departure time | E4: Platform Track Number | F4: EGTRAIN Tracklines
A5: BRESCIA | B5: Origin | D5: -3780
A6: Ospitaletto T | B6: Stop | C6: -3300 | D6: -3240 | E6: 2 | F6: B14
A7: ROVATO | B7: Stop | C7: -2940 | D7: -2880 | E7: 1 | F7: B27
A8: Chiari
A9: Calcio
A10: Romano
A11: Morengo Bariano
A12: Vidalengo
A13: TREVIGLIO
A14: P.M. Bivio Adda
A15: Bivio Casirate
A16: Melzo
A17: MELZO SCALO
A18: Vignate
A19: PIOLTELLO LIM.
... A21: MILANO LAMBRATE

Sheet 56064
A1: Train Number | B1: Train Category | C1: Origin | D1: Destination | E1: Mezzo di trazione | F1: Vel. veicoli e Rango
A2: 56064 | B2: TC | C2: PESCARA | D2: NOVARA BOSCHETTO | E2: E483 | F2: 120 A
A4: Stations | B4: Type of Stop | C4: Arrival time | D4: Departure time | E4: Platform Track Number | F4: EGTRAIN Tracklines
A5: BRESCIA | B5: Pass | D5: -3480
A6: Ospitaletto T | B6: Pass | D6: -2940 | E6: 2 | F6: B14
A7: ROVATO | B7: Pass | D7: -2640 | E7: 3 | F7: B14
A8: Chiari | B8: Pass | D8: -2280
A9: Calcio | B9: Pass | D9: -1920
A10: Romano | B10: Pass | D10: -1620 | E10: 1 | F10: B14
A11: Morengo Bariano | B11: Pass | D11: -1380
A12: Vidalengo | B12: Pass | D12: -1080
A13: TREVIGLIO | B13: Pass | D13: -840 | E13: 6 | F13: B12
A14: P.M. Bivio Adda | B14: Pass | D14: -720 | E14: 1 | F14: B12
A15: Bivio Casirate | B15: Pass | D15: -600
A16: Melzo
A17: MELZO SCALO | B17: Pass | D17: -300 | E17: 2 | F17: B4
A18: Vignate
A19: PIOLTELLO LIM. | B19: Pass | D19: 0 | E19: 4 | F19: B4
A20: Segrate
A21: MILANO LAMBRATE | B21: Pass | D21: 420

Sheet 10450
A1: Train Number | B1: Train Category | C1: Origin | D1: Destination | E1: Mezzo di trazione | F1: Vel. veicoli e Rango
A2: 10450 | B2: REG | C2: CREMONA | D2: MI.P.GARIBALDI | E2: E464 np | F2: 160 B
A4: Stations | B4: Type of Stop | C4: Arrival time | D4: Departure time | E4: Platform Track Number | F4: EGTRAIN Tracklines
A5: BRESCIA
A6: Ospitaletto T | G6: 71.653
A7: ROVATO | G7: 65.827
A8: Chiari | G8: 59.778
A9: Calcio | G9: 53.018
A10: Romano | G10: 46.052
A11: Morengo Bariano | G11: 42.117
A12: Route origin | D12: =C13-65 -> 115 | G12: 37.146
A13: TREVIGLIO | B13: Stop | C13: 180 | D13: 300 | E13: 7 | F13: B16 | G13: 33.143
A14: P.M. Bivio Adda | B14: Pass | D14: 480 | E14: 1 | F14: B12 | G14: 29.25
A15: Bivio Casirate | B15: Pass | D15: 600 | G15: 27.425
A16: Melzo | G16: 19.6
A17: MELZO SCALO | B17: Pass | D17: 900 | E17: 2 | F17: B4 | G17: 18.75
A18: Vignate | G18: 16.09
A19: PIOLTELLO LIM. | B19: Pass | D19: 1080 | E19: 4 | F19: B4 | G19: 12.31
A20: Segrate | G20: 9.9
A21: MILANO LAMBRATE | B21: Stop | C21: 1380 | D21: 1500

Sheet 23006
A1: Train Number | B1: Train Category | C1: Origin | D1: Destination | E1: Mezzo di trazione | F1: Vel. veicoli e Rango
A2: 23006 | B2: REG | C2: TREVIGLIO | D2: VARESE | E2: ALe 711/710 (2 + 3 | F2: 140 B
A4: Stations | B4: Type of Stop | C4: Arrival time | D4: Departure time | E4: Platform Track Number | F4: EGTRAIN Tracklines
G6: 71.653
G7: 65.827
G8: 59.778
G9: 53.018
G10: 46.052
G11: 42.117
A12: Entrance on route | D12: 531 | G12: 37.146
A13: TREVIGLIO | B13: Origin | D13: 600 | E13: 2 | F13: B26 | G13: 33.143
A14: P.M. Bivio Adda | B14: Pass | D14: 780 | E14: 4 | F14: B1 | G14: 29.25
A15: Bivio Casirate | G15: 27.425
A16: Melzo | B16: Stop | C16: 1680 | D16: 1740 | G16: 19.6
A17: MELZO SCALO | B17: Pass | D17: 1800 | E17: 2N | F17: B1 | G17: 18.75
A18: Vignate | B18: Stop | C18: 1920 | D18: 1980 | G18: 16.09
A19: PIOLTELLO LIM. | B19: Stop | C19: 2220 | D19: 2280 | E19: 2 | F19: B1 | G19: 12.31
A20: Segrate | B20: Stop | C20: 2460 | D20: 2520 | G20: 9.9
A21: MILANO LAMBRATE

Sheet 2602
A1: Train Number | B1: Train Category | C1: Origin | D1: Destination | E1: Mezzo di trazione | F1: Vel. veicoli e Rango
A2: 2602 | B2: REG | C2: BERGAMO | D2: MILANO CENTRALE | E2: E464 np | F2: 160 B
A4: Stations | B4: Type of Stop | C4: Arrival time | D4: Departure time | E4: Platform Track Number | F4: EGTRAIN Tracklines
A5: BRESCIA
A6: Ospitaletto T | G6: 71.653
A7: ROVATO | G7: 65.827
A8: Chiari | G8: 59.778
A9: Calcio | G9: 53.018
A10: Romano | G10: 46.052
A11: Morengo Bariano | G11: 42.117
A12: Entrance on Route | C12: =819-115 -> 704 | D12: =C19-C12 -> 1096 | G12: 37.146
A13: TREVIGLIO | G13: 33.143
A14: P.M. Bivio Adda | B14: Pass | D14: 1140 | E14: 1 | F14: B12 | G14: 29.25
A15: Bivio Casirate | B15: Pass | D15: 1260 | G15: 27.425
A16: Melzo | G16: 19.6
A17: MELZO SCALO | B17: Pass | D17: 1500 | E17: 2 | F17: B4 | G17: 18.75
A18: Vignate | G18: 16.09
A19: PIOLTELLO LIM. | B19: Stop | C19: 1800 | D19: 1860 | E19: 4 | F19: B4 | G19: 12.31
A20: Segrate | G20: 9.9
A21: MILANO LAMBRATE | B21: Stop | C21: 2340 | D21: 2460

Sheet 4902
A1: Train Number | B1: Train Category | C1: Origin | D1: Destination | E1: Mezzo di trazione | F1: Vel. veicoli e Rango
A2: 4902 | B2: REG | C2: BRESCIA | D2: BERGAMO | E2: ALe 582 (1M + 3R) | F2: 140 C
A4: Stations | B4: Type of Stop | C4: Arrival time | D4: Departure time | E4: Platform Track Number | F4: EGTRAIN Tracklines
A5: BRESCIA | B5: Origin | D5: -2340
A6: Ospitaletto T | B6: Stop | C6: -1860 | D6: -1800 | E6: 2 | F6: B14 | G6: 71.653
A7: ROVATO | B7: Stop | C7: -1500 | D7: -1440 | E7: 1 | F7: B27 | G7: 65.827
A8: Chiari | G8: 59.778
A9: Calcio | G9: 53.018
A10: Romano | G10: 46.052
A11: Morengo Bariano | G11: 42.117
A12: Vidalengo | G12: 37.146
A13: TREVIGLIO | G13: 33.143
A14: P.M. Bivio Adda | G14: 29.25
A15: Bivio Casirate | G15: 27.425
A16: Melzo | G16: 19.6
A17: MELZO SCALO | G17: 18.75
A18: Vignate | G18: 16.09
A19: PIOLTELLO LIM. | G19: 12.31
A20: Segrate | G20: 9.9
A21: MILANO LAMBRATE

Sheet 2096
A1: Train Number | B1: Train Category | C1: Origin | D1: Destination | E1: Mezzo di trazione | F1: Vel. veicoli e Rango
A2: 2096 | B2: REG | C2: BRESCIA | D2: MILANO CENTRALE | E2: E464 np | F2: 160 B
A4: Stations | B4: Type of Stop | C4: Arrival time | D4: Departure time | E4: Platform Track Number | F4: EGTRAIN Tracklines
A5: Entrance on route | D5: 13
A6: BRESCIA | B6: Origin | D6: -480
A7: Ospitaletto T | B7: Pass | D7: 60 | E7: 2 | F7: B14 | G7: 71.653
A8: ROVATO | B8: Stop | C8: 360 | D8: 420 | E8: 3 | F8: B14 | G8: 65.827
A9: Chiari | B9: Stop | C9: 660 | D9: 720 | G9: 59.778
A10: Calcio | B10: Pass | D10: 960 | G10: 53.018
A11: Romano | B11: Stop | C11: 1200 | D11: 1260 | E11: 1 | F11: B14 | G11: 46.052
A12: Morengo Bariano | B12: Pass | D12: 1440 | G12: 42.117
A13: Vidalengo | B13: Pass | D13: 1620 | G13: 37.146
A14: TREVIGLIO | B14: Stop | C14: 1860 | D14: 1980 | E14: 6 | F14: B12 | G14: 33.143
A15: P.M. Bivio Adda | B15: Pass | D15: 2100 | E15: 1 | F15: B12 | G15: 29.25
A16: Bivio Casirate | B16: Pass | D16: 2220 | G16: 27.425
A17: Melzo | G17: 19.6
A18: MELZO SCALO | B18: Pass | D18: 2460 | E18: 2 | F18: B4 | G18: 18.75
A19: Vignate | G19: 16.09
A20: PIOLTELLO LIM. | B20: Pass | D20: 2640 | E20: 4 | F20: B4 | G20: 12.31
A21: Segrate | G21: 9.9
A22: MILANO LAMBRATE | B22: Stop | C22: 3060 | D22: 3180

Sheet 4904
A1: Train Number | B1: Train Category | C1: Origin | D1: Destination | E1: Mezzo di trazione | F1: Vel. veicoli e Rango
A2: 4904 | B2: REG | C2: BRESCIA | D2: BERGAMO | E2: E464 np | F2: 140 B
A4: Stations | B4: Type of Stop | C4: Arrival time | D4: Departure time | E4: Platform Track Number | F4: EGTRAIN Tracklines
A5: EntranceonRoute | D5: =300-264 -> 36
A6: BRESCIA | B6: Origin | D6: -180
A7: Ospitaletto T | B7: Stop | C7: 300 | D7: 360 | E7: 2 | F7: B14
A8: ROVATO | B8: Stop | C8: 660 | D8: 720 | E8: 1 | F8: B27
A9: Chiari
A10: Calcio
A11: Romano
A12: Morengo Bariano
A13: Vidalengo
A14: TREVIGLIO
A15: P.M. Bivio Adda
A16: Bivio Casirate
A17: Melzo
A18: MELZO SCALO
A19: Vignate
A20: PIOLTELLO LIM.
... A22: MILANO LAMBRATE

Sheet 53214-53215-53214
A1: Train Number | B1: Train Category | C1: Origin | D1: Destination | E1: Mezzo di trazione | F1: Vel. veicoli e Rango
A2: 53214-53215-53214 | B2: TC | C2: PD INTERPORTO | D2: Ge Voltri FM | E2: E652 | F2: 100 A
A4: Stations | B4: Type of Stop | C4: Arrival time | D4: Departure time | E4: Platform Track Number | F4: EGTRAIN Tracklines
A5: EntranceonRoute | D5: =336-127 -> 209
A6: BRESCIA | B6: Pass | D6: 60
A7: Ospitaletto T | B7: Pass | D7: 600 | E7: 2 | F7: B14 | G7: 71.653
A8: ROVATO | B8: Pass | D8: 900 | E8: 3 | F8: B14 | G8: 65.827
A9: Chiari | B9: Pass | D9: 1140 | G9: 59.778
A10: Calcio | B10: Pass | D10: 1380 | G10: 53.018
A11: Romano | B11: Pass | D11: 1680 | E11: 1 | F11: B14 | G11: 46.052
A12: Morengo Bariano | B12: Pass | D12: 1860 | G12: 42.117
A13: Vidalengo | B13: Pass | D13: 2040 | G13: 37.146
A14: TREVIGLIO | B14: Pass | D14: 2220 | E14: 5 | F14: B11 | G14: 33.143
A15: P.M. Bivio Adda | B15: Pass | D15: 2400 | E15: 1 | F15: B12 | G15: 29.25
A16: Bivio Casirate | B16: Pass | D16: 2520 | G16: 27.425
A17: Melzo | G17: 19.6
A18: MELZO SCALO | B18: Pass | D18: 2820 | E18: 2 | F18: B4 | G18: 18.75
A19: Vignate | G19: 16.09
A20: PIOLTELLO LIM. | B20: Pass | D20: 3060 | E20: 4 | F20: B4 | G20: 12.31
A21: Segrate | G21: 9.9
A22: MILANO LAMBRATE

Sheet 10604
A1: Train Number | B1: Train Category | C1: Origin | D1: Destination | E1: Mezzo di trazione | F1: Vel. veicoli e Rango
A2: 10604 | B2: REG | C2: PIOLTELLO LIM. | D2: NOVARA | E2: ALe 711/710 (2 + 3 | F2: 140 B
A4: Stations | B4: Type of Stop | C4: Arrival time | D4: Departure time | E4: Platform Track Number | F4: EGTRAIN Tracklines
A5: BRESCIA
A6: Ospitaletto T | G6: 71.653
A7: ROVATO | G7: 65.827
A8: Chiari | G8: 59.778
A9: Calcio | G9: 53.018
A10: Romano | G10: 46.052
A11: Morengo Bariano | G11: 42.117
A12: Vidalengo | G12: 37.146
A13: TREVIGLIO | G13: 33.143
A14: P.M. Bivio Adda | G14: 29.25
A15: Bivio Casirate | G15: 27.425
A16: Melzo | G16: 19.6
A17: MELZO SCALO | G17: 18.75
A18: Origin onRoute | D18: =C20-126 -> 3234 | G18: 16.09
A19: PIOLTELLO LIM. | B19: Origin | D19: 3180 | E19: 1tr | F19: B3 | G19: 12.152
A20: Segrate | B20: Stop | C20: 3360 | D20: 3420 | G20: 9.9
A21: MILANO LAMBRATE

Sheet 23008
A1: Train Number | B1: Train Category | C1: Origin | D1: Destination | E1: Mezzo di trazione | F1: Vel. veicoli e Rango
A2: 23008 | B2: REG | C2: TREVIGLIO | D2: VARESE | E2: ALe 711/710 (2 + 3 | F2: 140 B
A4: Stations | B4: Type of Stop | C4: Arrival time | D4: Departure time | E4: Platform Track Number | F4: EGTRAIN Tracklines
A5: BRESCIA
A6: Ospitaletto T | G6: 71.653
A7: ROVATO | G7: 65.827
A8: Chiari | G8: 59.778
A9: Calcio | G9: 53.018
A10: Romano | G10: 46.052
A11: Morengo Bariano | G11: 42.117
A12: Entrance onRoute | D12: =531+1800 -> 2331 | G12: 37.146
A13: TREVIGLIO | B13: Origin | D13: 2400 | E13: 1 | F13: B25 | G13: 33.143
A14: P.M. Bivio Adda | B14: Pass | D14: 2580 | E14: 4 | F14: B1 | G14: 29.25
A15: Bivio Casirate | G15: 27.425
A16: Melzo | B16: Stop | C16: 3480 | D16: 3540 | G16: 19.6
A17: MELZO SCALO | B17: Pass | D17: 3600 | E17: 2N | F17: B1 | G17: 18.75
A18: Vignate | B18: Stop | C18: 3720 | D18: 3780 | G18: 16.09
A19: PIOLTELLO LIM. | B19: Stop | C19: 4020 | D19: 4080 | E19: 2 | F19: B1 | G19: 12.152
A20: Segrate | B20: Stop | C20: 4260 | D20: 4320 | G20: 9.9
A21: MILANO LAMBRATE

Sheet 10452
A1: Train Number | B1: Train Category | C1: Origin | D1: Destination | E1: Mezzo di trazione | F1: Vel. veicoli e Rango
A2: 10452 | B2: REG | C2: CREMONA | D2: MI.P.GARIBALDI | E2: E464 np | F2: 160 B
A4: Stations | B4: Type of Stop | C4: Arrival time | D4: Departure time | E4: Platform Track Number | F4: EGTRAIN Tracklines
A5: BRESCIA
A6: Ospitaletto T
A7: ROVATO
A8: Chiari
A9: Calcio
A10: Romano
A11: Morengo Bariano
A12: EntranceonRoute | D12: =115+H13 -> 2395
A13: TREVIGLIO | B13: Stop | C13: 2460 | D13: 2580 | E13: 7 | F13: B16 | H13: =C13-180 -> 2280
A14: P.M. Bivio Adda | B14: Pass | D14: 2760 | E14: 1 | F14: B12
A15: Bivio Casirate | B15: Pass | D15: 2820
A16: Melzo
A17: MELZO SCALO | B17: Pass | D17: 3120 | E17: 2 | F17: B4
A18: Vignate
A19: PIOLTELLO LIM. | B19: Pass | D19: 3300 | E19: 4 | F19: B4
A20: Segrate
A21: MILANO LAMBRATE | B21: Stop | C21: 3840 | D21: 3960

Sheet 10800
A1: Train Number | B1: Train Category | C1: Origin | D1: Destination | E1: Mezzo di trazione | F1: Vel. veicoli e Rango
A2: 10800 | B2: REG | C2: BERGAMO | D2: MI.P.GARIBALDI | E2: E464 np | F2: 140 B
A4: Stations | B4: Type of Stop | C4: Arrival time | D4: Departure time | E4: Platform Track Number | F4: EGTRAIN Tracklines
A5: BRESCIA
A6: Ospitaletto T | G6: 71.653
A7: ROVATO | G7: 65.827
A8: Chiari | G8: 59.778
A9: Calcio | G9: 53.018
A10: Romano | G10: 46.052
A11: Morengo Bariano | G11: 42.117
A12: EntranceonRoute | D12: =D14-197 -> 2923 | G12: 37.146
A13: TREVIGLIO | G13: 33.143
A14: P.M. Bivio Adda | B14: Pass | D14: 3120 | E14: 1 | F14: B12 | G14: 29.25
A15: Bivio Casirate | B15: Pass | D15: 3180 | G15: 27.425
A16: Melzo | G16: 19.6
A17: MELZO SCALO | B17: Pass | D17: 3420 | E17: 2 | F17: B4 | G17: 18.75
A18: Vignate | G18: 16.09
A19: PIOLTELLO LIM. | B19: Stop | C19: 3600 | D19: 3660 | E19: 2 | F19: B1 | G19: 12.152
A20: Segrate | B20: Pass | D20: 3840 | G20: 9.9
A21: MILANO LAMBRATE | B21: Stop | C21: 4440 | D21: 4560

Sheet 10714
A1: Train Number | B1: Train Category | C1: Origin | D1: Destination | E1: Mezzo di trazione | F1: Vel. veicoli e Rango
A2: 10714 | B2: REG | C2: BRESCIA | D2: MI.GRECO PIRELLI | E2: E464 np | F2: 140 B
A4: Stations | B4: Type of Stop | C4: Arrival time | D4: Departure time | E4: Platform Track Number | F4: EGTRAIN Tracklines
A5: EntranceonRoute | D5: =C7-264 -> 576
A6: BRESCIA | B6: Origin | D6: 360
A7: Ospitaletto T | B7: Stop | C7: 840 | D7: 900 | E7: 2 | F7: B14 | G7: 71.653
A8: ROVATO | B8: Stop | C8: 1200 | D8: 1260 | E8: 3 | F8: B14 | G8: 65.827
A9: Chiari | B9: Stop | C9: 1500 | D9: 1560 | G9: 59.778
A10: Calcio | B10: Stop | C10: 1800 | D10: 1860 | G10: 53.018
A11: Romano | B11: Stop | C11: 2160 | D11: 2220 | E11: 1 | F11: B14 | G11: 46.052
A12: Morengo Bariano | B12: Stop | C12: 2460 | D12: 2520 | G12: 42.117
A13: Vidalengo | B13: Stop | C13: 2760 | D13: 2820 | G13: 37.146
A14: TREVIGLIO | B14: Stop | C14: 3120 | D14: 3240 | E14: 6 | F14: B12 | G14: 33.143
A15: P.M. Bivio Adda | B15: Pass | D15: 3360 | E15: 1 | F15: B12 | G15: 29.25
A16: Bivio Casirate | B16: Pass | D16: 3420 | G16: 27.425
A17: Melzo | G17: 19.6
A18: MELZO SCALO | B18: Pass | D18: 3660 | E18: 2 | F18: B4 | G18: 18.75
A19: Vignate | G19: 16.09
A20: PIOLTELLO LIM. | B20: Stop | C20: 3900 | D20: 3960 | E20: 4 | F20: B4 | G20: 12.152
A21: Segrate | G21: 9.9
A22: MILANO LAMBRATE | B22: Stop | C22: 4680 | D22: 4800

Sheet 4906
A1: Train Number | B1: Train Category | C1: Origin | D1: Destination | E1: Mezzo di trazione | F1: Vel. veicoli e Rango
A2: 4906 | B2: REG | C2: BRESCIA | D2: BERGAMO | E2: E464 np | F2: 160 B
A4: Stations | B4: Type of Stop | C4: Arrival time | D4: Departure time | E4: Platform Track Number | F4: EGTRAIN Tracklines
A5: Entrance'OnRoute | D5: =D7-225 -> 1215
A6: BRESCIA | B6: Origin | D6: 1020
A7: Ospitaletto T | B7: Pass | D7: 1440 | E7: 2 | F7: B14
A8: ROVATO | B8: Stop | C8: 1680 | D8: 1740 | E8: 1 | F8: B27
A9: Chiari
A10: Calcio
A11: Romano
A12: Morengo Bariano
A13: Vidalengo
A14: TREVIGLIO
A15: P.M. Bivio Adda
A16: Bivio Casirate
A17: Melzo
A18: MELZO SCALO
A19: Vignate
A20: PIOLTELLO LIM.
... A22: MILANO LAMBRATE

Sheet 2054
A1: Train Number | B1: Train Category | C1: Origin | D1: Destination | E1: Mezzo di trazione | F1: Vel. veicoli e Rango
A2: 2054 | B2: REG | C2: VERONA P.NUOVA | D2: MILANO CENTRALE | E2: E464 np | F2: 160 B
A4: Stations | B4: Type of Stop | C4: Arrival time | D4: Departure time | E4: Platform Track Number | F4: EGTRAIN Tracklines
A5: Entrance OnRoute | D5: =D7-225 -> 1815
A6: BRESCIA | B6: Stop | C6: 1560 | D6: 1680
A7: Ospitaletto T | B7: Pass | D7: 2040 | E7: 2 | F7: B14 | G7: 71.653
A8: ROVATO | B8: Stop | C8: 2220 | D8: 2280 | E8: 3 | F8: B14 | G8: 65.827
A9: Chiari | B9: Stop | C9: 2580 | D9: 2640 | G9: 59.778
A10: Calcio | B10: Pass | D10: 2880 | G10: 53.018
A11: Romano | B11: Stop | C11: 3120 | D11: 3180 | E11: 1 | F11: B14 | G11: 46.052
A12: Morengo Bariano | B12: Pass | D12: 3360 | G12: 42.117
A13: Vidalengo | B13: Pass | D13: 3540 | G13: 37.146
A14: TREVIGLIO | B14: Stop | C14: 3780 | D14: 3900 | E14: 6 | F14: B12 | G14: 33.143
A15: P.M. Bivio Adda | B15: Pass | D15: 4080 | E15: 1 | F15: B12 | G15: 29.25
A16: Bivio Casirate | B16: Pass | D16: 4200 | G16: 27.425
A17: Melzo | G17: 19.6
A18: MELZO SCALO | B18: Pass | D18: 4440 | E18: 2 | F18: B4 | G18: 18.75
A19: Vignate | G19: 16.09
A20: PIOLTELLO LIM. | B20: Stop | C20: 4680 | D20: 4740 | E20: 4 | F20: B4 | G20: 12.152
A21: Segrate | G21: 9.9
A22: MILANO LAMBRATE | B22: Stop | C22: 5160 | D22: 5280

Sheet 233-232
A1: Train Number | B1: Train Category | C1: Origin | D1: Destination | E1: Mezzo di trazione | F1: Vel. veicoli e Rango
A2: 233-232 | B2: EN | C2: TARVISIO BOSCOV. | D2: MI.P.GARIBALDI | E2: E402 (101-180) | F2: 200 C
A4: Stations | B4: Type of Stop | C4: Arrival time | D4: Departure time | E4: Platform Track Number | F4: EGTRAIN Tracklines
A5: EntranceonRoute | D5: =D7-237 -> 2283
A6: BRESCIA | B6: Stop | C6: 1920 | D6: 2040
A7: Ospitaletto T | B7: Pass | D7: 2520 | E7: 2 | F7: B14 | G7: 71.653
A8: ROVATO | B8: Pass | D8: 2760 | E8: 3 | F8: B14 | G8: 65.827
A9: Chiari | B9: Pass | D9: 3060 | G9: 59.778
A10: Calcio | B10: Pass | D10: 3300 | G10: 53.018
A11: Romano | B11: Pass | D11: 3540 | E11: 1 | F11: B14 | G11: 46.052
A12: Morengo Bariano | B12: Pass | D12: 3720 | G12: 42.117
A13: Vidalengo | B13: Pass | D13: 3960 | G13: 37.146
A14: TREVIGLIO | B14: Pass | D14: 4260 | E14: 6 | F14: B12 | G14: 33.143
A15: P.M. Bivio Adda | B15: Pass | D15: 4380 | E15: 1 | F15: B12 | G15: 29.25
A16: Bivio Casirate | B16: Pass | D16: 4500 | G16: 27.425
A17: Melzo | G17: 19.6
A18: MELZO SCALO | B18: Pass | D18: 4800 | E18: 2 | F18: B4 | G18: 18.75
A19: Vignate | G19: 16.09
A20: PIOLTELLO LIM. | B20: Pass | D20: 5040 | E20: 4 | F20: B4 | G20: 12.152
A21: Segrate | G21: 9.9
A22: MILANO LAMBRATE | B22: Stop | C22: 5520 | D22: 5640

Sheet 10716
A1: Train Number | B1: Train Category | C1: Origin | D1: Destination | E1: Mezzo di trazione | F1: Vel. veicoli e Rango
A2: 10716 | B2: REG | C2: BRESCIA | D2: MI.GRECO PIRELLI | E2: E464 np | F2: 140 B
A4: Stations | B4: Type of Stop | C4: Arrival time | D4: Departure time | E4: Platform Track Number | F4: EGTRAIN Tracklines
A5: EntranceonRoute | D5: =C7-'10714'!C7+'10714'!D5 -> 2496
A6: BRESCIA | B6: Origin | D6: 2280
A7: Ospitaletto T | B7: Stop | C7: 2760 | D7: 2820 | E7: 2 | F7: B14 | G7: 71.653
A8: ROVATO | B8: Stop | C8: 3120 | D8: 3180 | E8: 3 | F8: B14 | G8: 65.827
A9: Chiari | B9: Stop | C9: 3420 | D9: 3480 | G9: 59.778
A10: Calcio | B10: Stop | C10: 3780 | D10: 3840 | G10: 53.018
A11: Romano | B11: Stop | C11: 4140 | D11: 4200 | E11: 1 | F11: B14 | G11: 46.052
A12: Morengo Bariano | B12: Stop | C12: 4440 | D12: 4500 | G12: 42.117
A13: Vidalengo | B13: Stop | C13: 4740 | D13: 4800 | G13: 37.146
A14: TREVIGLIO | B14: Stop | C14: 5100 | D14: 5220 | E14: 6 | F14: B12 | G14: 33.143
A15: P.M. Bivio Adda | B15: Pass | D15: 5400 | E15: 1 | F15: B12 | G15: 29.25
A16: Bivio Casirate | B16: Pass | D16: 5460 | G16: 27.425
A17: Melzo | G17: 19.6
A18: MELZO SCALO | B18: Pass | D18: 5700 | E18: 2 | F18: B4 | G18: 18.75
A19: Vignate | G19: 16.09
A20: PIOLTELLO LIM. | B20: Stop | C20: 5940 | D20: 6000 | E20: 4 | F20: B4 | G20: 12.152
A21: Segrate | G21: 9.9
A22: MILANO LAMBRATE | B22: Stop | C22: 6540 | D22: 6660

Sheet 9604-9609
A1: Train Number | B1: Train Category | C1: Origin | D1: Destination | E1: Mezzo di trazione | F1: Vel. veicoli e Rango
A2: 9604-9609 | B2: ES* | C2: BRESCIA | D2: NAPOLI CENTRALE | E2: ETR 500 AV | F2: 300 C
A4: Stations | B4: Type of Stop | C4: Arrival time | D4: Departure time | E4: Platform Track Number | F4: EGTRAIN Tracklines
A5: EntranceOnRoute | D5: =D16-970 -> 2810
A6: BRESCIA | B6: Origin | D6: 2520
A7: Ospitaletto T | G7: 71.653
A8: ROVATO | G8: 65.827
A9: Chiari | G9: 59.778
A10: Calcio | G10: 53.018
A11: Romano | G11: 46.052
A12: Morengo Bariano | G12: 42.117
A13: Vidalengo | G13: 37.146
A14: TREVIGLIO | G14: 33.143
A15: P.M. Bivio Adda | G15: 29.25
A16: Bivio Casirate | B16: Pass | D16: 3780 | G16: 27.425
A17: Melzo | G17: 19.6
A18: MELZO SCALO | B18: Pass | D18: 4020 | E18: 2 | F18: B4 | G18: 18.75
A19: Vignate | G19: 16.09
A20: PIOLTELLO LIM. | B20: Pass | D20: 4140 | E20: 4 | F20: B4 | G20: 12.152
A21: Segrate | G21: 9.9
A22: MILANO LAMBRATE | B22: Pass | D22: 4380

Sheet 10606
A1: Train Number | B1: Train Category | C1: Origin | D1: Destination | E1: Mezzo di trazione | F1: Vel. veicoli e Rango
A2: 10606 | B2: REG | C2: TREVIGLIO | D2: NOVARA | E2: ALe 711/710 (2 + 3 | F2: 140 B
A4: Stations | B4: Type of Stop | C4: Arrival time | D4: Departure time | E4: Platform Track Number | F4: EGTRAIN Tracklines
G6: 71.653
G7: 65.827
G8: 59.778
G9: 53.018
G10: 46.052
G11: 42.117
A12: EntranceonRoute | D12: =D13-39-30 -> 3231 | G12: 37.146
A13: TREVIGLIO | B13: Origin | D13: 3300 | E13: 2 | F13: B26 | G13: 33.143
A14: P.M. Bivio Adda | B14: Pass | D14: 3480 | E14: 4 | F14: B1 | G14: 29.25
A15: Bivio Casirate | G15: 27.425
A16: Melzo | B16: Stop | C16: 4380 | D16: 4440 | G16: 19.6
A17: MELZO SCALO | B17: Pass | D17: 4500 | E17: 2N | F17: B1 | G17: 18.75
A18: Vignate | B18: Stop | C18: 4620 | D18: 4680 | G18: 16.09
A19: PIOLTELLO LIM. | B19: Stop | C19: 4920 | D19: 4980 | E19: 2 | F19: B1 | G19: 12.152
A20: Segrate | B20: Stop | C20: 5160 | D20: 5220 | G20: 9.9
A21: MILANO LAMBRATE

Sheet 23010
A1: Train Number | B1: Train Category | C1: Origin | D1: Destination | E1: Mezzo di trazione | F1: Vel. veicoli e Rango
A2: 23010 | B2: REG | C2: TREVIGLIO | D2: VARESE | E2: ALe 711/710 (2 + 3 | F2: 140 B
A4: Stations | B4: Type of Stop | C4: Arrival time | D4: Departure time | E4: Platform Track Number | F4: EGTRAIN Tracklines
A12: OriginOnRoute | D12: =D13-'23008'!D13+'23008'!D12 -> 4131
A13: TREVIGLIO | B13: Origin | D13: 4200 | E13: 1 | F13: B25
A14: P.M. Bivio Adda | B14: Pass | D14: 4380 | E14: 4 | F14: B1
A15: Bivio Casirate
A16: Melzo | B16: Stop | C16: 5280 | D16: 5340
A17: MELZO SCALO | B17: Pass | D17: 5400 | E17: 2N | F17: B1
A18: Vignate | B18: Stop | C18: 5520 | D18: 5580
A19: PIOLTELLO LIM. | B19: Stop | C19: 5820 | D19: 5880 | E19: 2 | F19: B1
A20: Segrate | B20: Stop | C20: 6060 | D20: 6120
A21: MILANO LAMBRATE

Sheet 2604
A1: Train Number | B1: Train Category | C1: Origin | D1: Destination | E1: Mezzo di trazione | F1: Vel. veicoli e Rango
A2: 2604 | B2: REG | C2: BERGAMO | D2: MILANO CENTRALE | E2: E464 np | F2: 160 B
A4: Stations | B4: Type of Stop | C4: Arrival time | D4: Departure time | E4: Platform Track Number | F4: EGTRAIN Tracklines
G6: 71.653
G7: 65.827
G8: 59.778
G9: 53.018
G10: 46.052
G11: 42.117
A12: EntranceOnRoute | D12: =C19-'2602'!C19+'2602'!D12 -> 4696 | G12: 37.146
A13: TREVIGLIO | G13: 33.143
A14: P.M. Bivio Adda | B14: Pass | D14: 4740 | E14: 1 | F14: B12 | G14: 29.25
A15: Bivio Casirate | B15: Pass | D15: 4860 | G15: 27.425
A16: Melzo | G16: 19.6
A17: MELZO SCALO | B17: Pass | D17: 5100 | E17: 2 | F17: B4 | G17: 18.75
A18: Vignate | G18: 16.09
A19: PIOLTELLO LIM. | B19: Stop | C19: 5400 | D19: 5460 | E19: 4 | F19: B4 | G19: 12.152
A20: Segrate | G20: 9.9
A21: MILANO LAMBRATE | B21: Stop | C21: 5940 | D21: 6060

Sheet 10456
A1: Train Number | B1: Train Category | C1: Origin | D1: Destination | E1: Mezzo di trazione | F1: Vel. veicoli e Rango
A2: 10456 | B2: REG | C2: CREMONA | D2: MILANO CERTOSA | E2: E464 np | F2: 160 B
A4: Stations | B4: Type of Stop | C4: Arrival time | D4: Departure time | E4: Platform Track Number | F4: EGTRAIN Tracklines
G6: 71.653
G7: 65.827
G8: 59.778
G9: 53.018
G10: 46.052
G11: 42.117
A12: EntranceOnRoute | D12: ='10456'!C13-'10452'!C13+'10452'!D12 -> 4735 | G12: 37.146
A13: TREVIGLIO | B13: Stop | C13: 4800 | D13: 4920 | E13: 7 | F13: B16 | G13: 33.143
A14: P.M. Bivio Adda | B14: Pass | D14: 5100 | E14: 1 | F14: B12 | G14: 29.25
A15: Bivio Casirate | B15: Pass | D15: 5160 | G15: 27.425
A16: Melzo | G16: 19.6
A17: MELZO SCALO | B17: Pass | D17: 5400 | E17: 2 | F17: B4 | G17: 18.75
A18: Vignate | G18: 16.09
A19: PIOLTELLO LIM. | B19: Pass | D19: 5640 | E19: 2 | F19: B1 | G19: 12.152
A20: Segrate | B20: Pass | D20: 5760 | G20: 9.9
A21: MILANO LAMBRATE | B21: Stop | C21: 6240 | D21: 6360

Sheet 10610
A1: Train Number | B1: Train Category | C1: Origin | D1: Destination | E1: Mezzo di trazione | F1: Vel. veicoli e Rango
A2: 10610 | B2: REG | C2: TREVIGLIO | D2: NOVARA | E2: ALe 711/710 (2 + 3 | F2: 140 B
A4: Stations | B4: Type of Stop | C4: Arrival time | D4: Departure time | E4: Platform Track Number | F4: EGTRAIN Tracklines
G6: 71.653
G7: 65.827
G8: 59.778
G9: 53.018
G10: 46.052
G11: 42.117
A12: EntranceOnRoute | D12: =C16-'10606'!C16+'10606'!D12 -> 5031 | G12: 37.146
A13: TREVIGLIO | B13: Origin | D13: 5100 | E13: 2 | F13: B26 | G13: 33.143
A14: P.M. Bivio Adda | B14: Pass | D14: 5280 | E14: 4 | F14: B1 | G14: 29.25
A15: Bivio Casirate | G15: 27.425
A16: Melzo | B16: Stop | C16: 6180 | D16: 6240 | G16: 19.6
A17: MELZO SCALO | B17: Pass | D17: 6300 | E17: 2N | F17: B1 | G17: 18.75
A18: Vignate | B18: Stop | C18: 6420 | D18: 6480 | G18: 16.09
A19: PIOLTELLO LIM. | B19: Stop | C19: 6720 | D19: 6780 | E19: 2 | F19: B1 | G19: 12.152
A20: Segrate | B20: Stop | C20: 6960 | D20: 7020 | G20: 9.9
A21: MILANO LAMBRATE

Sheet Sheet1
A1: Train | B1: Line | C1: RevRoute | D1: Corridor | E1: 0 | F1: 1 | G1: 2 | H1: 3 | I1: 4 | J1: 5 | K1: 6 | L1: 7 | M1: 8 | N1: 9 | O1: 10 | P1: 11 | Q1: 12 | R1: 13 | S1: 14 | T1: 15 | U1: 16 | V1: 17 | W1: 18 | X1: 19 | Y1: 20 | Z1: 21 | AA1: 22 | AB1: 23 | AC1: 24 | AD1: 25 | AE1: 26 | AF1: 27 | AG1: 28 | AH1: 29 | AI1: 30 | AJ1: 31 | AK1: 32 | AL1: 33 | AM1: 34 | AN1: 35 | AO1: 36 | AP1: 37 | AQ1: 38 | AR1: 39 | AS1: 40 | AT1: 41 | AU1: 42 | AV1: 43 | AW1: 44 | AX1: 45 | AY1: 46 | AZ1: 47 | BA1: 48 | BB1: 49 | BC1: 50 | BD1: 51 | BE1: 52 | BF1: 53 | BG1: 54 | BH1: 55 | BI1: 56 | BJ1: 57 | BK1: 58 | BL1: 59 | BM1: 60 | BN1: 61 | BO1: 62 | BP1: 63 | BQ1: 64 | BR1: 65 | BS1: 66 | BT1: 67 | BU1: 68 | BV1: 69 | BW1: 70 | BX1: 71 | BY1: 72 | BZ1: 73 | CA1: 74 | CB1: 75 | CC1: 76 | CD1: 77 | CE1: 78 | CF1: 79 | CG1: 80 | CH1: 81 | CI1: 82 | CJ1: 83 | CK1: 84 | CL1: 85 | CM1: 86 | CN1: 87 | CO1: 88 | CP1: 89 | CQ1: 90 | CR1: 91 | CS1: 92 | CT1: 93 | CU1: 94 | CV1: 95 | CW1: 96 | CX1: 97 | CY1: 98 | CZ1: 99 | DA1: 100 | DB1: 101 | DC1: 102 | DD1: 103 | DE1: 104 | DF1: 105 | DG1: 106 | DH1: 107 | DI1: 108 | DJ1: 109 | DK1: 110 | DL1: 111 | DM1: 112 | DN1: 113 | DO1: 114 | DP1: 115 | DQ1: 116 | DR1: 117 | DS1: 118 | DT1: 119 | DU1: 120 | DV1: 121 | DW1: 122 | DX1: 123 | DY1: 124 | DZ1: 125 | EA1: 126 | EB1: 127 | EC1: 128 | ED1: 129 | EE1: 130 | EF1: 131 | EG1: 132 | EH1: 133 | EI1: 134 | EJ1: 135 | EK1: 136 | EL1: 137 | EM1: 138 | EN1: 139 | EO1: 140 | EP1: 141 | EQ1: 142 | ER1: 143 | ES1: 144 | ET1: 145 | EU1: 146 | EV1: 147 | EW1: 148 | EX1: 149 | EY1: 150 | EZ1: 151 | FA1: 152 | FB1: 153 | FC1: 154 | FD1: 155 | FE1: 156 | FF1: 157 | FG1: 158 | FH1: 159 | FI1: 160 | FJ1: 161 | FK1: 162 | FL1: 163 | FM1: 164 | FN1: 165 | FO1: 166 | FP1: 167 | FQ1: 168 | FR1: 169 | FS1: 170 | FT1: 171 | FU1: 172 | FV1: 173 | FW1: 174 | FX1: 175 | FY1: 176 | FZ1: 177 | GA1: 178 | GB1: 179 | GC1: 180 | GD1: 181 | GE1: 182 | GF1: 183 | GG1: 184 | GH1: 185 | GI1: 186 | GJ1: 187 | GK1: 188 | GL1: 189 | GM1: 190 | GN1: 191 | GO1: 192 | GP1: 193 | GQ1: 194 | GR1: 195 | GS1: 196 | GT1: 197 | GU1: 198 | GV1: 199 | GW1: 200 | GX1: 201 | GY1: 202 | GZ1: 203 | HA1: 204 | HB1: 205 | HC1: 206 | HD1: 207 | HE1: 208 | HF1: 209 | HG1: 210 | HH1: 211 | HI1: 212 | HJ1: 213 | HK1: 214 | HL1: 215 | HM1: 216 | HN1: 217 | HO1: 218 | HP1: 219 | HQ1: 220 | HR1: 221 | HS1: 222 | HT1: 223 | HU1: 224 | HV1: 225 | HW1: 226 | HX1: 227 | HY1: 228 | HZ1: 229 | IA1: 230 | IB1: 231 | IC1: 232 | ID1: 233 | IE1: 234 | IF1: 235 | IG1: 236 | IH1: 237 | II1: 238 | IJ1: 239 | IK1: 240 | IL1: 241 | IM1: 242 | IN1: 243 | IO1: 244 | IP1: 245 | IQ1: 246 | IR1: 247 | IS1: 248 | IT1: 249 | IU1: 250 | IV1: 251 | IW1: 252 | IX1: 253 | IY1: 254 | IZ1: 255 | JA1: 256 | JB1: 257 | JC1: 258 | JD1: 259 | JE1: 260 | JF1: 261 | JG1: 262 | JH1: 263 | JI1: 264 | JJ1: 265 | JK1: 266 | JL1: 267 | JM1: 268 | JN1: 269 | JO1: 270 | JP1: 271 | JQ1: 272 | JR1: 273 | JS1: 274 | JT1: 275 | JU1: 276 | JV1: 277 | JW1: 278 | JX1: 279 | JY1: 280 | JZ1: 281 | KA1: 282 | KB1: 283 | KC1: 284 | KD1: 285 | KE1: 286 | KF1: 287 | KG1: 288 | KH1: 289 | KI1: 290 | KJ1: 291 | KK1: 292 | KL1: 293 | KM1: 294 | KN1: 295 | KO1: 296 | KP1: 297 | KQ1: 298 | KR1: 299 | KS1: 300 | KT1: 301 | KU1: 302 | KV1: 303 | KW1: 304 | KX1: 305 | KY1: 306 | KZ1: 307 | LA1: 308 | LB1: 309 | LC1: 310 | LD1: 311 | LE1: 312 | LF1: 313 | LG1: 314 | LH1: 315 | LI1: 316 | LJ1: 317 | LK1: 318 | LL1: 319 | LM1: 320 | LN1: 321 | LO1: 322 | LP1: 323 | LQ1: 324 | LR1: 325 | LS1: 326 | LT1: 327 | LU1: 328 | LV1: 329 | LW1: 330 | LX1: 331 | LY1: 332 | LZ1: 333 | MA1: 334 | MB1: 335 | MC1: 336 | MD1: 337 | ME1: 338 | MF1: 339 | MG1: 340 | MH1: 341 | MI1: 342 | MJ1: 343 | MK1: 344 | ML1: 345 | MM1: 346 | MN1: 347 | MO1: 348 | MP1: 349 | MQ1: 350 | MR1: 351 | MS1: 352 | MT1: 353 | MU1: 354 | MV1: 355 | MW1: 356 | MX1: 357 | MY1: 358 | MZ1: 359 | NA1: 360 | NB1: 361 | NC1: 362 | ND1: 363 | NE1: 364 | NF1: 365 | NG1: 366 | NH1: 367 | NI1: 368 | NJ1: 369 | NK1: 370 | NL1: 371 | NM1: 372 | NN1: 373 | NO1: 374 | NP1: 375 | NQ1: 376 | NR1: 377 | NS1: 378 | NT1: 379 | NU1: 380 | NV1: 381 | NW1: 382 | NX1: 383 | NY1: 384 | NZ1: 385 | OA1: 386 | OB1: 387 | OC1: 388 | OD1: 389 | OE1: 390 | OF1: 391 | OG1: 392 | OH1: 393 | OI1: 394 | OJ1: 395 | OK1: 396 | OL1: 397 | OM1: 398 | ON1: 399 | OO1: 400 | OP1: 401 | OQ1: 402 | OR1: 403 | OS1: 404 | OT1: 405 | OU1: 406 | OV1: 407 | OW1: 408 | OX1: 409 | OY1: 410 | OZ1: 411 | PA1: 412 | PB1: 413 | PC1: 414 | PD1: 415 | PE1: 416 | PF1: 417 | PG1: 418 | PH1: 419 | PI1: 420 | PJ1: 421 | PK1: 422 | PL1: 423 | PM1: 424 | PN1: 425 | PO1: 426 | PP1: 427 | PQ1: 428 | PR1: 429 | PS1: 430 | PT1: 431 | PU1: 432 | PV1: 433 | PW1: 434 | PX1: 435 | PY1: 436 | PZ1: 437 | QA1: 438 | QB1: 439 | QC1: 440 | QD1: 441 | QE1: 442 | QF1: 443 | QG1: 444 | QH1: 445 | QI1: 446 | QJ1: 447 | QK1: 448 | QL1: 449 | QM1: 450 | QN1: 451 | QO1: 452 | QP1: 453 | QQ1: 454 | QR1: 455 | QS1: 456 | QT1: 457 | QU1: 458 | QV1: 459 | QW1: 460 | QX1: 461 | QY1: 462 | QZ1: 463 | RA1: 464 | RB1: 465 | RC1: 466 | RD1: 467 | RE1: 468 | RF1: 469 | RG1: 470 | RH1: 471 | RI1: 472 | RJ1: 473 | RK1: 474 | RL1: 475 | RM1: 476 | RN1: 477 | RO1: 478 | RP1: 479 | RQ1: 480 | RR1: 481 | RS1: 482 | RT1: 483 | RU1: 484 | RV1: 485 | RW1: 486 | RX1: 487 | RY1: 488 | RZ1: 489 | SA1: 490 | SB1: 491 | SC1: 492 | SD1: 493 | SE1: 494 | SF1: 495 | SG1: 496 | SH1: 497 | SI1: 498 | SJ1: 499 | SK1: 500 | SL1: 501 | SM1: 502 | SN1: 503 | SO1: 504 | SP1: 505 | SQ1: 506 | SR1: 507 | SS1: 508 | ST1: 509 | SU1: 510 | SV1: 511 | SW1: 512 | SX1: 513 | SY1: 514 | SZ1: 515 | TA1: 516 | TB1: 517 | TC1: 518 | TD1: 519 | TE1: 520 | TF1: 521 | TG1: 522 | TH1: 523 | TI1: 524 | TJ1: 525 | TK1: 526 | TL1: 527 | TM1: 528 | TN1: 529 | TO1: 530 | TP1: 531 | TQ1: 532 | TR1: 533 | TS1: 534 | TT1: 535 | TU1: 536 | TV1: 537 | TW1: 538 | TX1: 539 | TY1: 540 | TZ1: 541 | UA1: 542 | UB1: 543 | UC1: 544 | UD1: 545 | UE1: 546 | UF1: 547 | UG1: 548 | UH1: 549 | UI1: 550 | UJ1: 551 | UK1: 552 | UL1: 553 | UM1: 554 | UN1: 555 | UO1: 556 | UP1: 557 | UQ1: 558 | UR1: 559 | US1: 560 | UT1: 561 | UU1: 562 | UV1: 563 | UW1: 564 | UX1: 565 | UY1: 566 | UZ1: 567 | VA1: 568 | VB1: 569 | VC1: 570 | VD1: 571 | VE1: 572 | VF1: 573 | VG1: 574 | VH1: 575 | VI1: 576 | VJ1: 577 | VK1: 578 | VL1: 579 | VM1: 580 | VN1: 581 | VO1: 582 | VP1: 583 | VQ1: 584 | VR1: 585 | VS1: 586 | VT1: 587 | VU1: 588 | VV1: 589 | VW1: 590 | VX1: 591 | VY1: 592 | VZ1: 593 | WA1: 594 | WB1: 595 | WC1: 596 | WD1: 597 | WE1: 598 | WF1: 599 | WG1: 600 | WH1: 601 | WI1: 602 | WJ1: 603 | WK1: 604 | WL1: 605 | WM1: 606 | WN1: 607 | WO1: 608 | WP1: 609 | WQ1: 610 | WR1: 611 | WS1: 612 | WT1: 613 | WU1: 614 | WV1: 615 | WW1: 616 | WX1: 617 | WY1: 618 | WZ1: 619 | XA1: 620 | XB1: 621 | XC1: 622 | XD1: 623 | XE1: 624 | XF1: 625 | XG1: 626 | XH1: 627 | XI1: 628 | XJ1: 629 | XK1: 630 | XL1: 631 | XM1: 632 | XN1: 633 | XO1: 634 | XP1: 635 | XQ1: 636 | XR1: 637 | XS1: 638 | XT1: 639 | XU1: 640 | XV1: 641 | XW1: 642 | XX1: 643 | XY1: 644 | XZ1: 645 | YA1: 646 | YB1: 647 | YC1: 648 | YD1: 649 | YE1: 650 | YF1: 651 | YG1: 652 | YH1: 653 | YI1: 654 | YJ1: 655 | YK1: 656 | YL1: 657 | YM1: 658 | YN1: 659 | YO1: 660 | YP1: 661 | YQ1: 662 | YR1: 663 | YS1: 664 | YT1: 665 | YU1: 666 | YV1: 667 | YW1: 668 | YX1: 669 | YY1: 670 | YZ1: 671 | ZA1: 672 | ZB1: 673 | ZC1: 674 | ZD1: 675 | ZE1: 676 | ZF1: 677 | ZG1: 678 | ZH1: 679 | ZI1: 680 | ZJ1: 681 | ZK1: 682 | ZL1: 683 | ZM1: 684 | ZN1: 685 | ZO1: 686 | ZP1: 687 | ZQ1: 688 | ZR1: 689 | ZS1: 690 | ZT1: 691 | ZU1: 692 | ZV1: 693 | ZW1: 694 | ZX1: 695 | ZY1: 696 | ZZ1: 697 | AAA1: 698 | AAB1: 699 | AAC1: 700 | AAD1: 701 | AAE1: 702 | AAF1: 703 | AAG1: 704 | AAH1: 705 | AAI1: 706 | AAJ1: 707 | AAK1: 708 | AAL1: 709 | AAM1: 710 | AAN1: 711 | AAO1: 712 | AAP1: 713 | AAQ1: 714 | AAR1: 715 | AAS1: 716 | AAT1: 717 | AAU1: 718 | AAV1: 719 | AAW1: 720 | AAX1: 721 | AAY1: 722 | AAZ1: 723 | ABA1: 724 | ABB1: 725 | ABC1: 726 | ABD1: 727 | ABE1: 728 | ABF1: 729 | ABG1: 730 | ABH1: 731 | ABI1: 732 | ABJ1: 733 | ABK1: 734 | ABL1: 735 | ABM1: 736 | ABN1: 737 | ABO1: 738 | ABP1: 739 | ABQ1: 740 | ABR1: 741 | ABS1: 742 | ABT1: 743 | ABU1: 744 | ABV1: 745 | ABW1: 746 | ABX1: 747 | ABY1: 748 | ABZ1: 749 | ACA1: 750 | ACB1: 751 | ACC1: 752 | ACD1: 753 | ACE1: 754 | ACF1: 755 | ACG1: 756 | ACH1: 757 | ACI1: 758 | ACJ1: 759 | ACK1: 760 | ACL1: 761 | ACM1: 762 | ACN1: 763 | ACO1: 764 | ACP1: 765 | ACQ1: 766 | ACR1: 767 | ACS1: 768 | ACT1: 769 | ACU1: 770 | ACV1: 771 | ACW1: 772 | ACX1: 773 | ACY1: 774 | ACZ1: 775 | ADA1: 776 | ADB1: 777 | ADC1: 778 | ADD1: 779 | ADE1: 780 | ADF1: 781 | ADG1: 782 | ADH1: 783 | ADI1: 784 | ADJ1: 785 | ADK1: 786 | ADL1: 787 | ADM1: 788 | ADN1: 789 | ADO1: 790 | ADP1: 791 | ADQ1: 792 | ADR1: 793 | ADS1: 794 | ADT1: 795 | ADU1: 796 | ADV1: 797 | ADW1: 798 | ADX1: 799 | ADY1: 800 | ADZ1: 801 | AEA1: 802 | AEB1: 803 | AEC1: 804 | AED1: 805 | AEE1: 806 | AEF1: 807 | AEG1: 808 | AEH1: 809 | AEI1: 810 | AEJ1: 811 | AEK1: 812 | AEL1: 813 | AEM1: 814 | AEN1: 815 | AEO1: 816 | AEP1: 817 | AEQ1: 818 | AER1: 819 | AES1: 820 | AET1: 821 | AEU1: 822 | AEV1: 823 | AEW1: 824 | AEX1: 825 | AEY1: 826 | AEZ1: 827 | AFA1: 828 | AFB1: 829 | AFC1: 830 | AFD1: 831 | AFE1: 832 | AFF1: 833 | AFG1: 834 | AFH1: 835 | AFI1: 836 | AFJ1: 837 | AFK1: 838 | AFL1: 839 | AFM1: 840 | AFN1: 841 | AFO1: 842 | AFP1: 843 | AFQ1: 844 | AFR1: 845 | AFS1: 846 | AFT1: 847 | AFU1: 848 | AFV1: 849 | AFW1: 850 | AFX1: 851 | AFY1: 852 | AFZ1: 853 | AGA1: 854 | AGB1: 855 | AGC1: 856 | AGD1: 857 | AGE1: 858 | AGF1: 859 | AGG1: 860 | AGH1: 861 | AGI1: 862 | AGJ1: 863 | AGK1: 864 | AGL1: 865 | AGM1: 866 | AGN1: 867 | AGO1: 868 | AGP1: 869 | AGQ1: 870 | AGR1: 871 | AGS1: 872 | AGT1: 873 | AGU1: 874 | AGV1: 875 | AGW1: 876 | AGX1: 877 | AGY1: 878 | AGZ1: 879 | AHA1: 880 | AHB1: 881 | AHC1: 882 | AHD1: 883 | AHE1: 884 | AHF1: 885 | AHG1: 886 | AHH1: 887 | AHI1: 888 | AHJ1: 889 | AHK1: 890 | AHL1: 891 | AHM1: 892 | AHN1: 893 | AHO1: 894 | AHP1: 895 | AHQ1: 896 | AHR1: 897 | AHS1: 898 | AHT1: 899 | AHU1: 900 | AHV1: 901 | AHW1: 902 | AHX1: 903 | AHY1: 904 | AHZ1: 905 | AIA1: 906 | AIB1: 907 | AIC1: 908 | AID1: 909 | AIE1: 910 | AIF1: 911 | AIG1: 912 | AIH1: 913 | AII1: 914 | AIJ1: 915 | AIK1: 916 | AIL1: 917 | AIM1: 918 | AIN1: 919 | AIO1: 920 | AIP1: 921 | AIQ1: 922 | AIR1: 923 | AIS1: 924 | AIT1: 925 | AIU1: 926 | AIV1: 927 | AIW1: 928 | AIX1: 929 | AIY1: 930 | AIZ1: 931 | AJA1: 932 | AJB1: 933 | AJC1: 934 | AJD1: 935 | AJE1: 936 | AJF1: 937 | AJG1: 938 | AJH1: 939 | AJI1: 940 | AJJ1: 941 | AJK1: 942 | AJL1: 943 | AJM1: 944 | AJN1: 945 | AJO1: 946 | AJP1: 947 | AJQ1: 948 | AJR1: 949 | AJS1: 950 | AJT1: 951 | AJU1: 952 | AJV1: 953 | AJW1: 954 | AJX1: 955 | AJY1: 956 | AJZ1: 957 | AKA1: 958 | AKB1: 959 | AKC1: 960 | AKD1: 961 | AKE1: 962 | AKF1: 963 | AKG1: 964 | AKH1: 965 | AKI1: 966 | AKJ1: 967 | AKK1: 968 | AKL1: 969 | AKM1: 970 | AKN1: 971 | AKO1: 972 | AKP1: 973 | AKQ1: 974 | AKR1: 975 | AKS1: 976 | AKT1: 977 | AKU1: 978 | AKV1: 979 | AKW1: 980 | AKX1: 981 | AKY1: 982 | AKZ1: 983 | ALA1: 984 | ALB1: 985 | ALC1: 986 | ALD1: 987 | ALE1: 988 | ALF1: 989 | ALG1: 990 | ALH1: 991 | ALI1: 992 | ALJ1: 993 | ALK1: 994 | ALL1: 995 | ALM1: 996 | ALN1: 997 | ALO1: 998 | ALP1: 999
A2: TRAIN_AV1-1 | B2: 0 | C2: 0 | D2: A | E2: 0 | F2: 0 | G2: 0 | H2: 0 | I2: 0 | J2: 0 | K2: 0 | L2: 0 | M2: 0 | N2: 0 | O2: 0 | P2: 0 | Q2: 0 | R2: 0 | S2: 0 | T2: 0 | U2: 0 | V2: 0 | W2: 0 | X2: 0 | Y2: 0 | Z2: 0 | AA2: 0 | AB2: 0 | AC2: 0 | AD2: 0 | AE2: 0 | AF2: 0 | AG2: 0 | AH2: 0 | AI2: 0 | AJ2: 0 | AK2: 0 | AL2: 0 | AM2: 0 | AN2: 0 | AO2: 0 | AP2: 0 | AQ2: 0 | AR2: 0 | AS2: 0 | AT2: 0 | AU2: 0 | AV2: 0 | AW2: 0 | AX2: 0 | AY2: 0 | AZ2: 0 | BA2: 0 | BB2: 0 | BC2: 0 | BD2: 0 | BE2: 0 | BF2: 0 | BG2: 0 | BH2: 0 | BI2: 0 | BJ2: 0 | BK2: 0 | BL2: 0 | BM2: 0 | BN2: 0 | BO2: 0 | BP2: 0 | BQ2: 0 | BR2: 0 | BS2: 0 | BT2: 0 | BU2: 0 | BV2: 0 | BW2: 0 | BX2: 0 | BY2: 0 | BZ2: 0 | CA2: 0 | CB2: 0 | CC2: 0 | CD2: 0 | CE2: 0 | CF2: 0 | CG2: 0 | CH2: 0 | CI2: 0 | CJ2: 0 | CK2: 0 | CL2: 0 | CM2: 0 | CN2: 0 | CO2: 0 | CP2: 0 | CQ2: 0 | CR2: 0 | CS2: 0 | CT2: 0 | CU2: 0 | CV2: 0 | CW2: 0 | CX2: 0 | CY2: 0 | CZ2: 0 | DA2: 0 | DB2: 0.745503 | DC2: 2.23598 | DD2: 4.47084 | DE2: 7.4494 | DF2: 11.1709 | DG2: 15.6345 | DH2: 20.8393 | DI2: 26.7844 | DJ2: 33.4686 | DK2: 40.8908 | DL2: 49.0498 | DM2: 57.9444 | DN2: 67.5731 | DO2: 77.9346 | DP2: 88.9451 | DQ2: 100.581 | DR2: 112.82 | DS2: 125.64 | DT2: 139.022 | DU2: 152.946 | DV2: 167.394 | DW2: 182.349 | DX2: 197.795 | DY2: 213.715 | DZ2: 230.096 | EA2: 246.922 | EB2: 264.181 | EC2: 281.859 | ED2: 299.944 | EE2: 318.425 | EF2: 337.289 | EG2: 356.527 | EH2: 376.127 | EI2: 396.08 | EJ2: 416.377 | EK2: 437.008 | EL2: 457.964 | EM2: 479.237 | EN2: 500.819 | EO2: 522.702 | EP2: 544.879 | EQ2: 567.342 | ER2: 590.085 | ES2: 613.1 | ET2: 636.381 | EU2: 659.923 | EV2: 683.718 | EW2: 707.762 | EX2: 732.048 | EY2: 756.571 | EZ2: 781.326 | FA2: 806.308 | FB2: 831.512 | FC2: 856.933 | FD2: 882.567 | FE2: 908.409 | FF2: 934.455 | FG2: 960.7 | FH2: 987.141 | FI2: 1013.77 | FJ2: 1040.59 | FK2: 1067.6 | FL2: 1094.78 | FM2: 1122.15 | FN2: 1149.68 | FO2: 1177.39 | FP2: 1205.26 | FQ2: 1233.3 | FR2: 1261.5 | FS2: 1289.86 | FT2: 1318.37 | FU2: 1347.04 | FV2: 1375.86 | FW2: 1404.82 | FX2: 1433.93 | FY2: 1463.18 | FZ2: 1492.57 | GA2: 1522.1 | GB2: 1551.76 | GC2: 1581.55 | GD2: 1611.48 | GE2: 1641.54 | GF2: 1671.72 | GG2: 1702.02 | GH2: 1732.45 | GI2: 1763 | GJ2: 1793.67 | GK2: 1824.45 | GL2: 1855.35 | GM2: 1886.37 | GN2: 1917.49 | GO2: 1948.73 | GP2: 1980.07 | GQ2: 2011.52 | GR2: 2043.07 | GS2: 2074.73 | GT2: 2106.48 | GU2: 2138.34 | GV2: 2170.29 | GW2: 2202.34 | GX2: 2234.49 | GY2: 2266.73 | GZ2: 2299.07 | HA2: 2331.49 | HB2: 2364.01 | HC2: 2396.62 | HD2: 2429.32 | HE2: 2462.1 | HF2: 2494.98 | HG2: 2527.93 | HH2: 2560.97 | HI2: 2594.1 | HJ2: 2627.31 | HK2: 2660.59 | HL2: 2693.95 | HM2: 2727.39 | HN2: 2760.91 | HO2: 2794.49 | HP2: 2828.16 | HQ2: 2861.89 | HR2: 2895.69 | HS2: 2929.57 | HT2: 2963.51 | HU2: 2997.52 | HV2: 3031.6 | HW2: 3065.74 | HX2: 3099.96 | HY2: 3134.23 | HZ2: 3168.58 | IA2: 3202.98 | IB2: 3237.45 | IC2: 3271.99 | ID2: 3306.58 | IE2: 3341.24 | IF2: 3375.96 | IG2: 3410.74 | IH2: 3445.58 | II2: 3480.48 | IJ2: 3515.44 | IK2: 3550.46 | IL2: 3585.53 | IM2: 3620.66 | IN2: 3655.84 | IO2: 3691.09 | IP2: 3726.39 | IQ2: 3761.74 | IR2: 3797.15 | IS2: 3832.62 | IT2: 3868.14 | IU2: 3903.72 | IV2: 3939.35 | IW2: 3975.03 | IX2: 4010.77 | IY2: 4046.56 | IZ2: 4082.4 | JA2: 4118.28 | JB2: 4154.22 | JC2: 4190.21 | JD2: 4226.25 | JE2: 4262.33 | JF2: 4298.46 | JG2: 4334.64 | JH2: 4370.87 | JI2: 4407.14 | JJ2: 4443.46 | JK2: 4479.82 | JL2: 4516.23 | JM2: 4552.69 | JN2: 4589.19 | JO2: 4625.73 | JP2: 4662.31 | JQ2: 4698.94 | JR2: 4735.61 | JS2: 4772.32 | JT2: 4809.08 | JU2: 4845.88 | JV2: 4882.71 | JW2: 4919.59 | JX2: 4956.51 | JY2: 4993.46 | JZ2: 5030.46 | KA2: 5067.49 | KB2: 5104.57 | KC2: 5141.68 | KD2: 5178.84 | KE2: 5216.03 | KF2: 5253.26 | KG2: 5290.53 | KH2: 5327.83 | KI2: 5365.17 | KJ2: 5402.55 | KK2: 5439.97 | KL2: 5477.42 | KM2: 5514.9 | KN2: 5552.43 | KO2: 5589.99 | KP2: 5627.58 | KQ2: 5665.21 | KR2: 5702.87 | KS2: 5740.57 | KT2: 5778.31 | KU2: 5816.07 | KV2: 5853.87 | KW2: 5891.71 | KX2: 5929.57 | KY2: 5967.47 | KZ2: 6005.41 | LA2: 6043.37 | LB2: 6081.37 | LC2: 6119.4 | LD2: 6157.46 | LE2: 6195.55 | LF2: 6233.67 | LG2: 6271.83 | LH2: 6310.01 | LI2: 6348.23 | LJ2: 6386.47 | LK2: 6424.75 | LL2: 6463.05 | LM2: 6501.39 | LN2: 6539.75 | LO2: 6578.15 | LP2: 6616.57 | LQ2: 6655.02 | LR2: 6693.5 | LS2: 6732.01 | LT2: 6770.54 | LU2: 6809.1 | LV2: 6847.7 | LW2: 6886.31 | LX2: 6924.96 | LY2: 6963.63 | LZ2: 7002.33 | MA2: 7041.06 | MB2: 7079.81 | MC2: 7118.59 | MD2: 7157.4 | ME2: 7196.23 | MF2: 7235.09 | MG2: 7273.97 | MH2: 7312.87 | MI2: 7351.8 | MJ2: 7390.74 | MK2: 7429.71 | ML2: 7468.7 | MM2: 7507.72 | MN2: 7546.75 | MO2: 7585.81 | MP2: 7624.88 | MQ2: 7663.98 | MR2: 7703.09 | MS2: 7742.23 | MT2: 7781.38 | MU2: 7820.55 | MV2: 7859.75 | MW2: 7898.96 | MX2: 7938.18 | MY2: 7977.42 | MZ2: 8016.69 | NA2: 8055.96 | NB2: 8095.26 | NC2: 8134.58 | ND2: 8173.92 | NE2: 8213.28 | NF2: 8252.66 | NG2: 8292.07 | NH2: 8331.5 | NI2: 8370.94 | NJ2: 8410.41 | NK2: 8449.91 | NL2: 8489.42 | NM2: 8528.95 | NN2: 8568.51 | NO2: 8608.09 | NP2: 8647.68 | NQ2: 8687.3 | NR2: 8726.94 | NS2: 8766.6 | NT2: 8806.28 | NU2: 8845.98 | NV2: 8885.71 | NW2: 8925.45 | NX2: 8965.21 | NY2: 9004.99 | NZ2: 9044.79 | OA2: 9084.6 | OB2: 9124.44 | OC2: 9164.3 | OD2: 9204.17 | OE2: 9244.07 | OF2: 9283.98 | OG2: 9323.91 | OH2: 9363.86 | OI2: 9403.83 | OJ2: 9443.82 | OK2: 9483.82 | OL2: 9523.84 | OM2: 9563.88 | ON2: 9603.94 | OO2: 9644.01 | OP2: 9684.09 | OQ2: 9724.2 | OR2: 9764.32 | OS2: 9804.45 | OT2: 9844.6 | OU2: 9884.77 | OV2: 9924.96 | OW2: 9965.16 | OX2: 10005.4 | OY2: 10045.6 | OZ2: 10085.9 | PA2: 10126.1 | PB2: 10166.4 | PC2: 10206.7 | PD2: 10247 | PE2: 10287.4 | PF2: 10327.7 | PG2: 10368.1 | PH2: 10408.5 | PI2: 10448.9 | PJ2: 10489.3 | PK2: 10529.7 | PL2: 10570.1 | PM2: 10610.6 | PN2: 10651 | PO2: 10691.5 | PP2: 10732 | PQ2: 10772.5 | PR2: 10813 | PS2: 10853.6 | PT2: 10894.1 | PU2: 10934.7 | PV2: 10975.3 | PW2: 11015.9 | PX2: 11056.5 | PY2: 11097.2 | PZ2: 11137.8 | QA2: 11178.5 | QB2: 11219.2 | QC2: 11259.8 | QD2: 11300.6 | QE2: 11341.3 | QF2: 11382 | QG2: 11422.8 | QH2: 11463.5 | QI2: 11504.3 | QJ2: 11545.1 | QK2: 11585.9 | QL2: 11626.8 | QM2: 11667.6 | QN2: 11708.5 | QO2: 11749.3 | QP2: 11790.2 | QQ2: 11831.1 | QR2: 11872 | QS2: 11912.9 | QT2: 11953.9 | QU2: 11994.8 | QV2: 12035.8 | QW2: 12076.8 | QX2: 12117.8 | QY2: 12158.8 | QZ2: 12199.8 | RA2: 12240.8 | RB2: 12281.9 | RC2: 12322.9 | RD2: 12364 | RE2: 12405.1 | RF2: 12446.2 | RG2: 12487.3 | RH2: 12528.4 | RI2: 12569.6 | RJ2: 12610.7 | RK2: 12651.9 | RL2: 12693 | RM2: 12725.3 | RN2: 12750.8 | RO2: 12790.7 | RP2: 12829.9 | RQ2: 12868.3 | RR2: 12905.9 | RS2: 12942.9 | RT2: 12979 | RU2: 13014.4 | RV2: 13049.1 | RW2: 13083.1 | RX2: 13116.3 | RY2: 13148.8 | RZ2: 13180.6 | SA2: 13211.6 | SB2: 13242 | SC2: 13271.6 | SD2: 13300.5 | SE2: 13328.7 | SF2: 13356.3 | SG2: 13383.1 | SH2: 13409.2 | SI2: 13434.6 | SJ2: 13459.4 | SK2: 13483.4 | SL2: 13506.8 | SM2: 13529.5 | SN2: 13551.5 | SO2: 13572.8 | SP2: 13593.4 | SQ2: 13613.4 | SR2: 13632.7 | SS2: 13651.4 | ST2: 13669.4 | SU2: 13686.7 | SV2: 13703.4 | SW2: 13719.4 | SX2: 13734.7 | SY2: 13749.4 | SZ2: 13763.5 | TA2: 13776.8 | TB2: 13789.6 | TC2: 13801.7 | TD2: 13813.1 | TE2: 13823.9 | TF2: 13834.1 | TG2: 13843.6 | TH2: 13852.5 | TI2: 13860.7 | TJ2: 13868.3 | TK2: 13875.3 | TL2: 13881.6 | TM2: 13887.3 | TN2: 13892.3 | TO2: 13896.8 | TP2: 13900.5 | TQ2: 13903.7 | TR2: 13906.2 | TS2: 13908.1 | TT2: 13909.4 | TU2: 13910 | TV2: 13910 | TW2: 13910 | TX2: 13910 | TY2: 13910 | TZ2: 13910.7 | UA2: 13912.2 | UB2: 13914.5 | UC2: 13917.5 | UD2: 13921.2 | UE2: 13925.6 | UF2: 13930.8 | UG2: 13936.8 | UH2: 13943.5 | UI2: 13950.9 | UJ2: 13959.1 | UK2: 13967.9 | UL2: 13977.6 | UM2: 13987.9 | UN2: 13998.9 | UO2: 14010.6 | UP2: 14022.8 | UQ2: 14035.6 | UR2: 14049 | US2: 14062.9 | UT2: 14077.4 | UU2: 14092.4 | UV2: 14107.8 | UW2: 14123.7 | UX2: 14140.1 | UY2: 14156.9 | UZ2: 14174.2 | VA2: 14191.9 | VB2: 14209.9 | VC2: 14228.4 | VD2: 14247.3 | VE2: 14266.5 | VF2: 14286.1 | VG2: 14306.1 | VH2: 14326.4 | VI2: 14347 | VJ2: 14368 | VK2: 14389.2 | VL2: 14410.8 | VM2: 14432.7 | VN2: 14454.9 | VO2: 14477.3 | VP2: 14500.1 | VQ2: 14523.1 | VR2: 14546.4 | VS2: 14569.9 | VT2: 14593.7 | VU2: 14617.8 | VV2: 14642.1 | VW2: 14666.6 | VX2: 14691.3 | VY2: 14716.3 | VZ2: 14741.5 | WA2: 14766.9 | WB2: 14792.6 | WC2: 14818.4 | WD2: 14844.5 | WE2: 14870.7 | WF2: 14897.1 | WG2: 14923.8 | WH2: 14950.6 | WI2: 14977.6 | WJ2: 15004.8 | WK2: 15032.2 | WL2: 15059.7 | WM2: 15087.4 | WN2: 15115.3 | WO2: 15143.3 | WP2: 15171.5 | WQ2: 15199.9 | WR2: 15228.4 | WS2: 15257 | WT2: 15285.9 | WU2: 15314.8 | WV2: 15343.9 | WW2: 15373.2 | WX2: 15402.6 | WY2: 15432.1 | WZ2: 15461.8 | XA2: 15491.6 | XB2: 15521.5 | XC2: 15551.5 | XD2: 15581.7 | XE2: 15612 | XF2: 15642.5 | XG2: 15673 | XH2: 15703.7 | XI2: 15734.5 | XJ2: 15765.4 | XK2: 15796.4 | XL2: 15827.5 | XM2: 15858.7 | XN2: 15890.1 | XO2: 15921.5 | XP2: 15953.1 | XQ2: 15984.7 | XR2: 16016.5 | XS2: 16048.4 | XT2: 16080.3 | XU2: 16112.4 | XV2: 16144.5 | XW2: 16176.8 | XX2: 16209.1 | XY2: 16241.6 | XZ2: 16274.1 | YA2: 16306.7 | YB2: 16339.4 | YC2: 16372.2 | YD2: 16405.1 | YE2: 16438 | YF2: 16471.1 | YG2: 16504.2 | YH2: 16537.4 | YI2: 16570.7 | YJ2: 16604.1 | YK2: 16637.5 | YL2: 16671 | YM2: 16704.7 | YN2: 16738.3 | YO2: 16772.1 | YP2: 16805.9 | YQ2: 16839.8 | YR2: 16873.8 | YS2: 16907.8 | YT2: 16942 | YU2: 16976.2 | YV2: 17010.4 | YW2: 17044.7 | YX2: 17079.1 | YY2: 17113.6 | YZ2: 17148.1 | ZA2: 17182.7 | ZB2: 17217.3 | ZC2: 17252.1 | ZD2: 17286.8 | ZE2: 17321.7 | ZF2: 17356.6 | ZG2: 17391.6 | ZH2: 17426.6 | ZI2: 17461.7 | ZJ2: 17496.8 | ZK2: 17532 | ZL2: 17567.3 | ZM2: 17602.6 | ZN2: 17638 | ZO2: 17673.4 | ZP2: 17708.9 | ZQ2: 17744.4 | ZR2: 17780 | ZS2: 17815.6 | ZT2: 17851.3 | ZU2: 17887.1 | ZV2: 17922.9 | ZW2: 17958.8 | ZX2: 17994.7 | ZY2: 18030.6 | ZZ2: 18066.6 | AAA2: 18102.7 | AAB2: 18138.8 | AAC2: 18174.9 | AAD2: 18211.1 | AAE2: 18247.4 | AAF2: 18283.6 | AAG2: 18320 | AAH2: 18356.4 | AAI2: 18392.8 | AAJ2: 18429.3 | AAK2: 18465.8 | AAL2: 18502.3 | AAM2: 18538.9 | AAN2: 18575.6 | AAO2: 18612.3 | AAP2: 18649 | AAQ2: 18685.8 | AAR2: 18722.6 | AAS2: 18759.5 | AAT2: 18796.4 | AAU2: 18833.3 | AAV2: 18870.3 | AAW2: 18907.3 | AAX2: 18944.4 | AAY2: 18981.5 | AAZ2: 19018.6 | ABA2: 19055.8 | ABB2: 19093 | ABC2: 19130.3 | ABD2: 19167.6 | ABE2: 19204.9 | ABF2: 19242.3 | ABG2: 19279.7 | ABH2: 19317.1 | ABI2: 19354.6 | ABJ2: 19392.1 | ABK2: 19429.7 | ABL2: 19467.3 | ABM2: 19504.9 | ABN2: 19542.5 | ABO2: 19580.2 | ABP2: 19618 | ABQ2: 19655.7 | ABR2: 19693.5 | ABS2: 19731.3 | ABT2: 19769.2 | ABU2: 19807.1 | ABV2: 19845 | ABW2: 19883 | ABX2: 19921 | ABY2: 19959 | ABZ2: 19997 | ACA2: 20035.1 | ACB2: 20073.2 | ACC2: 20111.4 | ACD2: 20149.6 | ACE2: 20187.8 | ACF2: 20226 | ACG2: 20264.3 | ACH2: 20302.6 | ACI2: 20340.9 | ACJ2: 20379.3 | ACK2: 20417.6 | ACL2: 20456.1 | ACM2: 20494.5 | ACN2: 20533 | ACO2: 20571.5 | ACP2: 20610 | ACQ2: 20648.6 | ACR2: 20687.1 | ACS2: 20725.8 | ACT2: 20764.4 | ACU2: 20803.1 | ACV2: 20841.8 | ACW2: 20880.5 | ACX2: 20919.2 | ACY2: 20958 | ACZ2: 20996.8 | ADA2: 21035.6 | ADB2: 21074.5 | ADC2: 21113.3 | ADD2: 21152.2 | ADE2: 21191.2 | ADF2: 21230.1 | ADG2: 21269.1 | ADH2: 21308.1 | ADI2: 21347.1 | ADJ2: 21386.2 | ADK2: 21425.2 | ADL2: 21464.3 | ADM2: 21503.5 | ADN2: 21542.6 | ADO2: 21581.8 | ADP2: 21621 | ADQ2: 21660.2 | ADR2: 21699.4 | ADS2: 21738.7 | ADT2: 21778 | ADU2: 21817.3 | ADV2: 21856.6 | ADW2: 21895.9 | ADX2: 21935.3 | ADY2: 21974.7 | ADZ2: 22014.1 | AEA2: 22053.5 | AEB2: 22093 | AEC2: 22132.5 | AED2: 22172 | AEE2: 22211.5 | AEF2: 22251 | AEG2: 22290.6 | AEH2: 22330.2 | AEI2: 22369.8 | AEJ2: 22409.4 | AEK2: 22449 | AEL2: 22488.7 | AEM2: 22528.4 | AEN2: 22568.1 | AEO2: 22607.8 | AEP2: 22647.5 | AEQ2: 22687.3 | AER2: 22727.1 | AES2: 22766.9 | AET2: 22806.7 | AEU2: 22846.6 | AEV2: 22886.4 | AEW2: 22926.3 | AEX2: 22966.2 | AEY2: 23006.1 | AEZ2: 23046.1 | AFA2: 23086 | AFB2: 23126 | AFC2: 23166 | AFD2: 23206 | AFE2: 23246.1 | AFF2: 23286.1 | AFG2: 23326.2 | AFH2: 23366.3 | AFI2: 23406.4 | AFJ2: 23446.5 | AFK2: 23486.6 | AFL2: 23526.8 | AFM2: 23567 | AFN2: 23607.2 | AFO2: 23647.4 | AFP2: 23687.6 | AFQ2: 23727.9 | AFR2: 23768.1 | AFS2: 23808.4 | AFT2: 23848.7 | AFU2: 23889 | AFV2: 23929.3 | AFW2: 23969.7 | AFX2: 24010.1 | AFY2: 24050.4 | AFZ2: 24090.8 | AGA2: 24131.3 | AGB2: 24171.7 | AGC2: 24212.1 | AGD2: 24252.6 | AGE2: 24293.1 | AGF2: 24333.6 | AGG2: 24374.1 | AGH2: 24414.6 | AGI2: 24455.1 | AGJ2: 24495.7 | AGK2: 24536.3 | AGL2: 24576.9 | AGM2: 24617.5 | AGN2: 24658.1 | AGO2: 24698.7 | AGP2: 24739.4 | AGQ2: 24780 | AGR2: 24820.7 | AGS2: 24861.4 | AGT2: 24902.1 | AGU2: 24942.9 | AGV2: 24983.6 | AGW2: 25024.4 | AGX2: 25065.1 | AGY2: 25105.9 | AGZ2: 25146.7 | AHA2: 25187.5 | AHB2: 25228.3 | AHC2: 25269.2 | AHD2: 25310 | AHE2: 25350.9 | AHF2: 25391.8 | AHG2: 25432.7 | AHH2: 25473.6 | AHI2: 25514.5 | AHJ2: 25555.5 | AHK2: 25596.4 | AHL2: 25637.4 | AHM2: 25678.4 | AHN2: 25719.4 | AHO2: 25760.4 | AHP2: 25801.4 | AHQ2: 25842.4 | AHR2: 25883.5 | AHS2: 25924.5 | AHT2: 25965.6 | AHU2: 26006.7 | AHV2: 26047.7 | AHW2: 26088.8 | AHX2: 26130 | AHY2: 26171.1 | AHZ2: 26212.2 | AIA2: 26253.4 | AIB2: 26294.5 | AIC2: 26335.7 | AID2: 26376.9 | AIE2: 26418.1 | AIF2: 26459.3 | AIG2: 26500.5 | AIH2: 26541.8 | AII2: 26583 | AIJ2: 26624.3 | AIK2: 26665.6 | AIL2: 26706.8 | AIM2: 26748.1 | AIN2: 26789.4 | AIO2: 26830.8 | AIP2: 26872.1 | AIQ2: 26913.4 | AIR2: 26954.8 | AIS2: 26996.2 | AIT2: 27037.5 | AIU2: 27078.9 | AIV2: 27120.3 | AIW2: 27161.7 | AIX2: 27203.1 | AIY2: 27244.6 | AIZ2: 27286 | AJA2: 27327.5 | AJB2: 27368.9 | AJC2: 27410.4 | AJD2: 27451.9 | AJE2: 27493.4 | AJF2: 27534.9 | AJG2: 27576.4 | AJH2: 27618 | AJI2: 27659.5 | AJJ2: 27701 | AJK2: 27742.6 | AJL2: 27784.2 | AJM2: 27825.8 | AJN2: 27867.4 | AJO2: 27909 | AJP2: 27950.6 | AJQ2: 27992.2 | AJR2: 28033.8 | AJS2: 28075.5 | AJT2: 28117.1 | AJU2: 28158.8 | AJV2: 28200.5 | AJW2: 28242.2 | AJX2: 28283.9 | AJY2: 28325.6 | AJZ2: 28367.3 | AKA2: 28409 | AKB2: 28450.7 | AKC2: 28492.5 | AKD2: 28534.3 | AKE2: 28576 | AKF2: 28617.8 | AKG2: 28659.6 | AKH2: 28701.4 | AKI2: 28743.2 | AKJ2: 28785 | AKK2: 28826.9 | AKL2: 28868.7 | AKM2: 28910.6 | AKN2: 28952.4 | AKO2: 28994.3 | AKP2: 29036.2 | AKQ2: 29078.1 | AKR2: 29120 | AKS2: 29161.9 | AKT2: 29203.8 | AKU2: 29245.7 | AKV2: 29287.7 | AKW2: 29329.6 | AKX2: 29371.6 | AKY2: 29413.6 | AKZ2: 29455.5 | ALA2: 29497.5 | ALB2: 29539.5 | ALC2: 29581.5 | ALD2: 29623.5 | ALE2: 29665.6 | ALF2: 29707.6 | ALG2: 29749.6 | ALH2: 29791.7 | ALI2: 29833.8 | ALJ2: 29875.8 | ALK2: 29917.9 | ALL2: 29960 | ALM2: 30002.1 | ALN2: 30044.2 | ALO2: 30086.3 | ALP2: 30128.4
